{
 "cells": [
  {
   "attachments": {},
   "cell_type": "markdown",
   "metadata": {},
   "source": [
    "17 june assignment solution"
   ]
  },
  {
   "attachments": {},
   "cell_type": "markdown",
   "metadata": {},
   "source": [
    "1. What is the role of try and exception block ?"
   ]
  },
  {
   "attachments": {},
   "cell_type": "markdown",
   "metadata": {},
   "source": [
    "Ans1.The role of a \"try\" and \"except\" block, often referred to as an exception handling mechanism, is to handle and manage exceptions in a program.\n",
    "\n",
    "In programming, an exception is an event that occurs during the execution of a program that disrupts the normal flow of instructions. It usually indicates an error or an exceptional condition that needs to be handled in a special way.\n",
    "\n",
    "Here's how a try-except block works:\n",
    "\n",
    "1.The \"try\" block is used to enclose the code that might raise an exception. It is the section where you anticipate potential exceptions.\n",
    "\n",
    "2.If an exception occurs within the \"try\" block, the execution of the block is immediately stopped, and the program looks for an appropriate \"except\" block to handle the exception.\n",
    "\n",
    "3.The \"except\" block contains the code that is executed when a specific exception, or a type of exception, is raised. It specifies the exception type(s) that it can handle.\n",
    "\n",
    "4.When an exception occurs, the program checks each \"except\" block in order. If the raised exception matches the type specified in an \"except\" block, that block's code is executed, and the program continues executing from the next statement after the entire try-except construct.\n",
    "\n",
    "5.If no matching \"except\" block is found, the exception is propagated up the call stack to the next higher level of exception handling (either in an outer try-except block or to the default exception handler), or the program terminates with an unhandled exception error.\n",
    "\n",
    "The try-except block allows you to gracefully handle exceptions, preventing them from causing the program to crash abruptly. It provides a way to catch and deal with exceptional situations, such as invalid input, file I/O errors, network errors, or any unexpected behavior that might occur during program execution."
   ]
  },
  {
   "attachments": {},
   "cell_type": "markdown",
   "metadata": {},
   "source": [
    "2. What is the syntax for a basic try-except block?"
   ]
  },
  {
   "attachments": {},
   "cell_type": "markdown",
   "metadata": {},
   "source": [
    "Ans2.In Python, the syntax for a basic try-except block is as follows:"
   ]
  },
  {
   "cell_type": "code",
   "execution_count": null,
   "metadata": {},
   "outputs": [],
   "source": [
    "try:\n",
    "    # Code that might raise an exception\n",
    "    # ...\n",
    "except ExceptionType:\n",
    "    # Code to handle the exception\n",
    "    # ..."
   ]
  },
  {
   "attachments": {},
   "cell_type": "markdown",
   "metadata": {},
   "source": [
    "Here's an explanation of each part:\n",
    "\n",
    "1.The try keyword marks the beginning of the try block and is followed by a colon (:).\n",
    "\n",
    "2.Inside the try block, you write the code that you expect might raise an exception.\n",
    "\n",
    "3.If an exception occurs within the try block, the execution of the try block is immediately stopped, and the control is transferred to the except block.\n",
    "\n",
    "4.The except keyword is followed by the specific type of exception you want to catch, such as ValueError, TypeError, or NameError. You can also use a generic Exception type to catch all exceptions. It's generally recommended to be more specific about the types of exceptions you handle.\n",
    "\n",
    "5.After the exception type, you put a colon (:).\n",
    "\n",
    "6.Inside the except block, you write the code to handle the exception. This block is executed when the corresponding exception is raised.\n",
    "\n",
    "7.You can have multiple except blocks to handle different types of exceptions.\n",
    "\n",
    "8.Optionally, you can have a final else block that executes if no exceptions were raised in the try block.\n",
    "\n",
    "9.Optionally, you can have a finally block that always executes, regardless of whether an exception occurred or not. The code in the finally block is generally used for cleanup operations.\n",
    "\n",
    "Here's an example that demonstrates the basic try-except syntax:"
   ]
  },
  {
   "cell_type": "code",
   "execution_count": 10,
   "metadata": {},
   "outputs": [
    {
     "name": "stdout",
     "output_type": "stream",
     "text": [
      "Cannot divide by zero.\n"
     ]
    }
   ],
   "source": [
    "try:\n",
    "    num1 = int(input(\"Enter a number: \")) \n",
    "    num2 = int(input(\"Enter another number: \"))\n",
    "    result = num1 / num2\n",
    "    print(\"The result is:\", result)\n",
    "except ValueError:\n",
    "    print(\"Invalid input. Please enter a valid integer.\") # 12/ a\n",
    "except ZeroDivisionError:\n",
    "    print(\"Cannot divide by zero.\") # 12/0"
   ]
  },
  {
   "attachments": {},
   "cell_type": "markdown",
   "metadata": {},
   "source": [
    "In this example, the code inside the try block attempts to perform division on two numbers entered by the user. If the user enters invalid input (e.g., non-numeric characters), a ValueError will be raised and caught by the first except block. If the user enters 0 as the second number, a ZeroDivisionError will be raised and caught by the second except block."
   ]
  },
  {
   "attachments": {},
   "cell_type": "markdown",
   "metadata": {},
   "source": [
    "3. What happens if an exception occurs inside a try block and there is no matching\n",
    "except block?"
   ]
  },
  {
   "attachments": {},
   "cell_type": "markdown",
   "metadata": {},
   "source": [
    "Ans3.\n",
    "If an exception occurs inside a try block and there is no matching except block to handle that specific exception, the program execution will be terminated, and an error message will be displayed. This error message typically includes the traceback information, which shows the sequence of function calls and the line numbers where the exception occurred.\n",
    "\n",
    "Here's an example to illustrate this scenario in Python:"
   ]
  },
  {
   "cell_type": "code",
   "execution_count": 12,
   "metadata": {},
   "outputs": [
    {
     "ename": "ZeroDivisionError",
     "evalue": "division by zero",
     "output_type": "error",
     "traceback": [
      "\u001b[1;31m---------------------------------------------------------------------------\u001b[0m",
      "\u001b[1;31mZeroDivisionError\u001b[0m                         Traceback (most recent call last)",
      "Cell \u001b[1;32mIn[12], line 3\u001b[0m\n\u001b[0;32m      1\u001b[0m \u001b[39mtry\u001b[39;00m:\n\u001b[0;32m      2\u001b[0m     \u001b[39m# Some code that may raise an exception\u001b[39;00m\n\u001b[1;32m----> 3\u001b[0m     result \u001b[39m=\u001b[39m \u001b[39m10\u001b[39;49m \u001b[39m/\u001b[39;49m \u001b[39m0\u001b[39;49m  \u001b[39m# Division by zero raises a ZeroDivisionError\u001b[39;00m\n\u001b[0;32m      4\u001b[0m \u001b[39mexcept\u001b[39;00m \u001b[39mValueError\u001b[39;00m:\n\u001b[0;32m      5\u001b[0m     \u001b[39m# This except block won't handle the ZeroDivisionError\u001b[39;00m\n\u001b[0;32m      6\u001b[0m     \u001b[39mprint\u001b[39m(\u001b[39m\"\u001b[39m\u001b[39mCaught a ValueError\u001b[39m\u001b[39m\"\u001b[39m)\n",
      "\u001b[1;31mZeroDivisionError\u001b[0m: division by zero"
     ]
    }
   ],
   "source": [
    "try:\n",
    "    # Some code that may raise an exception\n",
    "    result = 10 / 0  # Division by zero raises a ZeroDivisionError\n",
    "except ValueError:\n",
    "    # This except block won't handle the ZeroDivisionError\n",
    "    print(\"Caught a ValueError\")"
   ]
  },
  {
   "attachments": {},
   "cell_type": "markdown",
   "metadata": {},
   "source": [
    "In the above code, the try block attempts to perform a division by zero, which raises a ZeroDivisionError. However, the except block is specifically designed to catch ValueError exceptions. Since there is no matching except block for ZeroDivisionError, the program execution will be halted, and an error message will be displayed, indicating the unhandled exception.\n",
    "\n",
    "To handle exceptions properly and avoid program termination, it's important to include except blocks that can handle the specific exceptions that may occur within the try block."
   ]
  },
  {
   "attachments": {},
   "cell_type": "markdown",
   "metadata": {},
   "source": [
    "4. What is the difference between using a bare except block and specifying a specific\n",
    "exception type?"
   ]
  },
  {
   "attachments": {},
   "cell_type": "markdown",
   "metadata": {},
   "source": [
    "Ans4.In Python, when handling exceptions, there is a difference between using a bare except block and specifying a specific exception type.\n",
    "\n",
    "1.Bare except block:\n",
    "When you use a bare except block, it means that you are catching all exceptions indiscriminately, regardless of the type of exception that occurred. Here's an example:"
   ]
  },
  {
   "cell_type": "code",
   "execution_count": null,
   "metadata": {},
   "outputs": [],
   "source": [
    "try:\n",
    "    # Some code that may raise an exception\n",
    "    ...\n",
    "except:\n",
    "    # Exception handling code\n",
    "    ..."
   ]
  },
  {
   "attachments": {},
   "cell_type": "markdown",
   "metadata": {},
   "source": [
    "Using a bare except block can be convenient in some cases, as it allows you to catch any exception that occurs and handle it in a generic way. However, it has some drawbacks:\n",
    "\n",
    "(a).It can make it harder to debug your code since you're not explicitly identifying the type of exception that occurred.\n",
    "\n",
    "(b).It can inadvertently catch and handle exceptions that you didn't intend to catch, including system-level exceptions or errors that should not be ignored.\n",
    "\n",
    "(c).It can mask programming errors or logical issues in your code by hiding the actual exception type.\n",
    "\n",
    "2.Specific exception type:\n",
    "On the other hand, specifying a specific exception type allows you to catch only the specified exception and any subclasses of that exception. By explicitly mentioning the exception type, you have more control over the types of exceptions you handle. Here's an example:"
   ]
  },
  {
   "cell_type": "code",
   "execution_count": null,
   "metadata": {},
   "outputs": [],
   "source": [
    "try:\n",
    "    # Some code that may raise an exception\n",
    "    ...\n",
    "except ValueError:\n",
    "    # Exception handling code for ValueError\n",
    "    ..."
   ]
  },
  {
   "attachments": {},
   "cell_type": "markdown",
   "metadata": {},
   "source": [
    "Using a specific exception type provides the following benefits:\n",
    "\n",
    "(i).It makes your code more readable and self-documenting by clearly indicating the expected exception types.\n",
    "\n",
    "(ii).t helps you handle different types of exceptions differently, tailoring the handling to specific situations.\n",
    "\n",
    "(iii).It allows other exceptions to propagate up the call stack, which can be helpful for debugging and identifying issues.\n",
    "\n",
    "In general, it is recommended to use specific exception types whenever possible, as it leads to more robust and maintainable code. However, there may be scenarios where a bare except block is appropriate, such as when you want to log or handle unexpected exceptions in a generic way."
   ]
  },
  {
   "attachments": {},
   "cell_type": "markdown",
   "metadata": {},
   "source": [
    "5. Can you have nested try-except blocks in Python? If yes, then give an example"
   ]
  },
  {
   "attachments": {},
   "cell_type": "markdown",
   "metadata": {},
   "source": [
    "Ans5.Yes, you can have nested try-except blocks in Python. This allows you to handle different levels of exceptions in a more granular manner. Here's an example:"
   ]
  },
  {
   "cell_type": "code",
   "execution_count": 27,
   "metadata": {},
   "outputs": [
    {
     "name": "stdout",
     "output_type": "stream",
     "text": [
      "Error: Division by zero!\n"
     ]
    },
    {
     "ename": "NameError",
     "evalue": "name 'outer_variable' is not defined",
     "output_type": "error",
     "traceback": [
      "\u001b[1;31m---------------------------------------------------------------------------\u001b[0m",
      "\u001b[1;31mZeroDivisionError\u001b[0m                         Traceback (most recent call last)",
      "Cell \u001b[1;32mIn[27], line 3\u001b[0m\n\u001b[0;32m      1\u001b[0m \u001b[39mtry\u001b[39;00m:\n\u001b[0;32m      2\u001b[0m     \u001b[39m# Outer try block\u001b[39;00m\n\u001b[1;32m----> 3\u001b[0m     outer_variable \u001b[39m=\u001b[39m \u001b[39m10\u001b[39;49m \u001b[39m/\u001b[39;49m \u001b[39m0\u001b[39;49m  \u001b[39m# This will raise a ZeroDivisionError\u001b[39;00m\n\u001b[0;32m      4\u001b[0m \u001b[39mexcept\u001b[39;00m \u001b[39mZeroDivisionError\u001b[39;00m:\n",
      "\u001b[1;31mZeroDivisionError\u001b[0m: division by zero",
      "\nDuring handling of the above exception, another exception occurred:\n",
      "\u001b[1;31mNameError\u001b[0m                                 Traceback (most recent call last)",
      "Cell \u001b[1;32mIn[27], line 8\u001b[0m\n\u001b[0;32m      5\u001b[0m \u001b[39mprint\u001b[39m(\u001b[39m\"\u001b[39m\u001b[39mError: Division by zero!\u001b[39m\u001b[39m\"\u001b[39m)\n\u001b[0;32m      6\u001b[0m \u001b[39mtry\u001b[39;00m:\n\u001b[0;32m      7\u001b[0m     \u001b[39m# Inner try block\u001b[39;00m\n\u001b[1;32m----> 8\u001b[0m     inner_variable \u001b[39m=\u001b[39m outer_variable \u001b[39m/\u001b[39m \u001b[39m0\u001b[39m  \u001b[39m# This will raise a ZeroDivisionError as well\u001b[39;00m\n\u001b[0;32m      9\u001b[0m \u001b[39mexcept\u001b[39;00m \u001b[39mZeroDivisionError\u001b[39;00m:\n\u001b[0;32m     10\u001b[0m     \u001b[39mprint\u001b[39m(\u001b[39m\"\u001b[39m\u001b[39mError: Nested division by zero!\u001b[39m\u001b[39m\"\u001b[39m)\n",
      "\u001b[1;31mNameError\u001b[0m: name 'outer_variable' is not defined"
     ]
    }
   ],
   "source": [
    "try:\n",
    "    # Outer try block\n",
    "    outer_variable = 10 / 0  # This will raise a ZeroDivisionError\n",
    "except ZeroDivisionError:\n",
    "    print(\"Error: Division by zero!\")\n",
    "    try:\n",
    "        # Inner try block\n",
    "        inner_variable = outer_variable / 0  # This will raise a ZeroDivisionError as well\n",
    "    except ZeroDivisionError:\n",
    "        print(\"Error: Nested division by zero!\")"
   ]
  },
  {
   "attachments": {},
   "cell_type": "markdown",
   "metadata": {},
   "source": [
    "In the above example, we have an outer try block that attempts to perform a division by zero, which raises a ZeroDivisionError. Inside the except block for the outer try block, we have an inner try block. Within the inner try block, we perform another division by zero, which also raises a ZeroDivisionError. The inner except block then catches this nested exception and executes the corresponding code.\n",
    "\n",
    "Note that in this example, we are reusing the same exception type (ZeroDivisionError) for both the outer and inner try-except blocks, but you can have different types of exceptions in each level as needed."
   ]
  },
  {
   "attachments": {},
   "cell_type": "markdown",
   "metadata": {},
   "source": [
    "6. Can we use multiple exception blocks, if yes then give an example."
   ]
  },
  {
   "attachments": {},
   "cell_type": "markdown",
   "metadata": {},
   "source": [
    "ANS6.Yes, it is possible to use multiple exception blocks in a programming language that supports exception handling. Each exception block can handle a specific type of exception or a group of related exceptions.\n",
    "\n",
    "Here's an example in Python:"
   ]
  },
  {
   "cell_type": "code",
   "execution_count": null,
   "metadata": {},
   "outputs": [
    {
     "name": "stdout",
     "output_type": "stream",
     "text": [
      "Invalid input. Please enter a valid number.\n",
      "This block will always be executed.\n"
     ]
    }
   ],
   "source": [
    "try:\n",
    "    # Code that may raise exceptions\n",
    "    num1 = int(input(\"Enter a number: \"))\n",
    "    num2 = int(input(\"Enter another number: \"))\n",
    "    result = num1 / num2\n",
    "\n",
    "except ValueError:\n",
    "    print(\"Invalid input. Please enter a valid number.\")\n",
    "\n",
    "except ZeroDivisionError:\n",
    "    print(\"Cannot divide by zero.\")\n",
    "\n",
    "except Exception as e:\n",
    "    print(\"An error occurred:\", e)\n",
    "\n",
    "else:\n",
    "    print(\"The result is:\", result)\n",
    "\n",
    "finally:\n",
    "    print(\"This block will always be executed.\")"
   ]
  },
  {
   "attachments": {},
   "cell_type": "markdown",
   "metadata": {},
   "source": [
    "In the above example, there are multiple exception blocks:\n",
    "\n",
    "The first except block catches ValueError if the user enters an invalid number.\n",
    "\n",
    "The second except block catches ZeroDivisionError if the user enters zero as the second number.\n",
    "\n",
    "The third except block catches any other exceptions that may occur and assigns it to the variable e.\n",
    "\n",
    "The else block executes if no exceptions were raised.\n",
    "\n",
    "The finally block always executes, regardless of whether an exception occurred or not.\n",
    "\n",
    "By using multiple exception blocks, you can handle different types of exceptions separately and perform appropriate actions based on the type of exception encountered."
   ]
  },
  {
   "attachments": {},
   "cell_type": "markdown",
   "metadata": {},
   "source": [
    "7. Write the reason due to which following errors are raised:\n",
    "\n",
    "a. EOFError\n",
    "\n",
    "b. FloatingPointError\n",
    "\n",
    "c. IndexError\n",
    "\n",
    "d. MemoryError\n",
    "\n",
    "e. OverflowError\n",
    "\n",
    "f. TabError\n",
    "\n",
    "g. ValueErro"
   ]
  },
  {
   "attachments": {},
   "cell_type": "markdown",
   "metadata": {},
   "source": [
    "Ans7. (a)The EOFError is raised when the input() function or a similar function encounters an end-of-file (EOF) condition. This error typically occurs when attempting to read input from a source, such as a file or standard input (e.g., the terminal), and the source unexpectedly reaches its end.\n",
    "\n",
    "Here are some possible reasons for encountering an EOFError:\n",
    "\n",
    "1.End of file while reading from a file: If you're reading input from a file using functions like readline() or read(), an EOFError may occur when you reach the end of the file. This can happen if you attempt to read beyond the file's contents without checking for the end condition.\n",
    "\n",
    "2.Prematurely closing a file: If you explicitly close a file using the close() method and then attempt to read from it afterward, an EOFError can be raised. Once a file is closed, any subsequent read operation will result in an EOFError because the file handle is no longer accessible.\n",
    "\n",
    "3.Keyboard interrupt during input: When reading from standard input (e.g., the terminal), an EOFError can be raised if the user interrupts the input process by pressing a specific key combination. For example, in many systems, pressing Ctrl+D (or Ctrl+Z on Windows) can signal the end of input, leading to an EOFError.\n",
    "\n",
    "4.Redirecting input from an empty source: If you're running a script that expects input from a redirected source (e.g., python script.py < input.txt), an EOFError can occur if the input file is empty or does not exist. In such cases, the input source provides no data, resulting in an immediate end-of-file condition.\n",
    "\n",
    "To handle an EOFError, you can use exception handling mechanisms like try and except to catch the error and handle it appropriately. It's essential to anticipate and account for potential end-of-file situations when reading input, especially when dealing with external sources like files or user input."
   ]
  },
  {
   "attachments": {},
   "cell_type": "markdown",
   "metadata": {},
   "source": [
    "(b) The FloatingPointError is raised in programming languages to indicate an error related to floating-point arithmetic operations. Here are a few common reasons why a FloatingPointError may be raised:\n",
    "\n",
    "1.Division by zero: When you attempt to divide a number by zero in floating-point arithmetic, it results in an undefined or infinite value. This division by zero can trigger a FloatingPointError since it violates the rules of arithmetic.\n",
    "\n",
    "2.Overflow or underflow: Floating-point numbers have limited precision, and if the result of a computation exceeds the maximum representable value (overflow) or falls below the minimum representable value (underflow), a FloatingPointError may be raised. This typically occurs when performing calculations with extremely large or extremely small numbers.\n",
    "\n",
    "3.Invalid operations: Some floating-point operations are not well-defined or are mathematically invalid. For example, taking the square root of a negative number or performing logarithms on non-positive numbers can result in a FloatingPointError.\n",
    "\n",
    "4.NaN (Not a Number) propagation: NaN is a special value used to represent the result of undefined or non-representable operations. If a NaN value is involved in subsequent computations, it can propagate and eventually lead to a FloatingPointError.\n",
    "\n",
    "5.System-specific errors: Depending on the programming language and environment, there may be additional reasons for a FloatingPointError to occur. These can include issues with floating-point hardware or settings, precision limitations imposed by the language, or specific implementation-related constraints.\n",
    "\n",
    "When encountering a FloatingPointError, it is essential to carefully examine the context and code that triggered the error to determine the specific cause and apply appropriate fixes or error handling mechanisms."
   ]
  },
  {
   "attachments": {},
   "cell_type": "markdown",
   "metadata": {},
   "source": [
    "(c) An IndexError is raised when there is an attempt to access an index that is outside the valid range of indices for a data structure, such as a list or an array. This error typically occurs in programming languages that use zero-based indexing, where the indices start from 0.\n",
    "\n",
    "Here are some common reasons for an IndexError:\n",
    "\n",
    "1.Accessing an element beyond the bounds of a list: If you try to access an element at an index that is greater than or equal to the length of a list, an IndexError will be raised. For example, if you have a list with five elements and you try to access the element at index 5, it will result in an IndexError.\n",
    "\n",
    "2.Accessing a negative index: In some programming languages, negative indexing is allowed to access elements from the end of a list. However, if you use a negative index that is greater than or equal to the negative length of the list, an IndexError will be raised. For instance, if you have a list with five elements and you try to access the element at index -6, it will raise an IndexError.\n",
    "\n",
    "3.Accessing an element in an empty list: When you try to access an element from an empty list, i.e., a list with no elements, an IndexError will be raised. Since there are no elements in the list, there are no valid indices to access.\n",
    "\n",
    "4.Accessing elements in nested data structures: If you are working with nested data structures like lists of lists or dictionaries of lists, an IndexError can occur if you try to access an index that does not exist in one of the nested structures. For example, if you have a list of lists and you try to access an element using an index that is valid for the outer list but not for the inner list, it will raise an IndexError.\n",
    "\n",
    "5.Misunderstanding the valid range of indices: It's important to understand the valid range of indices for a particular data structure. Some programming languages start indexing from 0, while others may start from 1. Attempting to access an index outside the valid range based on the indexing convention of the language will result in an IndexError.\n",
    "\n",
    "In summary, an IndexError is raised when there is an attempt to access an invalid index, either by going beyond the bounds of a data structure, using negative indices incorrectly, accessing elements in an empty list, or misunderstanding the valid range of indices."
   ]
  },
  {
   "attachments": {},
   "cell_type": "markdown",
   "metadata": {},
   "source": [
    "(d) A MemoryError is raised when a program tries to allocate more memory than is available in the system. This error typically occurs when a program exhausts the available memory resources and is unable to allocate additional memory to perform the requested operation. Here are some common reasons for a MemoryError:\n",
    "\n",
    "1.Insufficient physical memory: If the system does not have enough physical memory (RAM) to accommodate the memory requirements of a program, a MemoryError can be raised. This can happen when a program consumes large amounts of memory due to factors such as handling large datasets, processing complex computations, or using inefficient memory management techniques.\n",
    "\n",
    "2.Memory leaks: A memory leak occurs when a program fails to release memory that is no longer needed, leading to a gradual accumulation of unreleased memory. If a program has a memory leak issue and continues to allocate memory without releasing it, it can eventually result in a MemoryError as the available memory is fully utilized.\n",
    "\n",
    "3.Large data structures: If a program attempts to create or manipulate large data structures, such as multidimensional arrays, matrices, or large lists, it can consume a significant amount of memory. If the available memory is insufficient to accommodate these data structures, a MemoryError can occur.\n",
    "\n",
    "4.Recursive functions or infinite loops: Recursive functions and infinite loops can consume excessive memory if not designed or terminated properly. Each recursive function call or iteration of an infinite loop adds a new frame to the call stack, which consumes memory. If the recursion depth or loop iterations exceed the available memory resources, a MemoryError can be raised.\n",
    "\n",
    "5.External resource limitations: In some cases, the available memory for a program may be restricted by external factors such as system settings, operating system limitations, or virtual memory constraints. These limitations can vary depending on the system configuration and can lead to a MemoryError if the program exceeds the allowed memory allocation.\n",
    "\n",
    "It's important to note that the specific causes of a MemoryError can vary depending on the programming language, the operating system, and the specific context in which the error occurs. Addressing MemoryErrors often involves optimizing memory usage, improving memory management strategies, or redesigning algorithms to reduce memory consumption."
   ]
  },
  {
   "attachments": {},
   "cell_type": "markdown",
   "metadata": {},
   "source": [
    "(e) An OverflowError is raised when a calculation or operation results in a value that exceeds the maximum representable value for a given data type. This error typically occurs in situations where the calculated value is too large to be stored or processed within the available memory or data range.\n",
    "\n",
    "Here are some common reasons why an OverflowError may be raised:\n",
    "\n",
    "1.Integer Overflow: When performing arithmetic operations with integers, if the result of the operation exceeds the maximum value that can be represented by the integer data type, an OverflowError will occur. For example, if you add two large integers together and the result is larger than the maximum value for the integer data type, the error will be raised.\n",
    "\n",
    "2.Floating-Point Overflow: Floating-point numbers have a finite range of representable values. If a calculation involving floating-point numbers produces a result that is too large to be represented within the available range, an OverflowError will be raised. This can happen when performing operations like multiplication, exponentiation, or division with large values.\n",
    "\n",
    "3.Recursion or Iteration: Recursive or iterative algorithms that involve repetitive calculations can lead to an OverflowError if the calculated values grow exponentially or beyond the limit of the data type being used. This can occur when solving certain mathematical problems or when implementing algorithms that rely on repeated calculations.\n",
    "\n",
    "4.External Data or Input: If external data or user input is involved in a calculation and it contains values that exceed the limits of the data type being used, an OverflowError can be raised. For example, if a program expects user input in the form of integers and the user enters a value that is too large to be represented by the integer data type, the error will occur.\n",
    "\n",
    "To resolve an OverflowError, you may need to reconsider the data type used for storing or representing values, use larger data types that can accommodate larger values, or modify your algorithm or calculation to avoid excessive growth or overflow of values."
   ]
  },
  {
   "attachments": {},
   "cell_type": "markdown",
   "metadata": {},
   "source": [
    "(f) A TabError is raised in Python when there is an issue with the indentation of code. Python relies on consistent indentation to define the structure and hierarchy of code blocks, such as loops and conditional statements. The specific reasons for a TabError can vary, but here are some common scenarios:\n",
    "\n",
    "1.Mixing Tabs and Spaces: Python expects consistent use of either tabs or spaces for indentation. If a code file contains a mixture of tabs and spaces, it can result in a TabError. For example, if you use a tab for one level of indentation and then switch to spaces for another level, Python may raise a TabError to indicate the inconsistency.\n",
    "\n",
    "2.Incorrect Indentation Level: Python uses indentation to define the scope of code blocks. If the indentation levels are not consistent within a block of code, Python will raise a TabError. For instance, if a line of code within a block is indented at a different level than the previous lines, it can trigger the error.\n",
    "\n",
    "3.Missing or Extra Indentation: Python expects code blocks to be indented properly, and deviations can lead to a TabError. If a line of code is not indented when it should be or if there is unnecessary indentation, Python will raise the error. This commonly occurs when defining functions, loops, or conditional statements.\n",
    "\n",
    "4.Inconsistent Indentation Style: Python conventionally recommends using four spaces for indentation. If a codebase has inconsistent indentation styles, such as using two spaces in some places and four spaces in others, it may result in a TabError.\n",
    "\n",
    "It is important to note that TabError is a subclass of the IndentationError in Python, which is raised when there are general issues with indentation. However, the specific name TabError is used when the error is specifically related to tab and space inconsistencies.\n",
    "\n",
    "\n",
    "\n",
    "\n"
   ]
  },
  {
   "attachments": {},
   "cell_type": "markdown",
   "metadata": {},
   "source": [
    "(g) The \"ValueError\" is a commonly raised error in programming languages. It occurs when a function or operation receives an argument of the correct type but an inappropriate value. Here are a few reasons why a \"ValueError\" can occur:\n",
    "\n",
    "1.Incorrect argument type: The function or operation expects a certain data type for its argument, but a value of a different data type is provided. For example, if a function expects an integer as an argument but receives a string instead, a \"ValueError\" may be raised.\n",
    "\n",
    "2.Out-of-range values: Some functions or operations have restrictions on the range of acceptable values. If an argument exceeds the allowed range, a \"ValueError\" can be raised. For instance, if a function expects a positive number but receives a negative value, a \"ValueError\" may occur.\n",
    "\n",
    "3.Invalid format: Certain operations require data to be in a specific format or adhere to a particular pattern. If the provided value does not meet the required format or pattern, a \"ValueError\" can be raised. For example, if a function expects a date in the format \"YYYY-MM-DD\" but receives a date in a different format, a \"ValueError\" might occur.\n",
    "\n",
    "4.Inconsistent input: Some functions or operations rely on multiple arguments or values that need to be consistent with each other. If the provided values are incompatible or contradict each other, a \"ValueError\" can be raised. For instance, if a function expects a start time and an end time, but the start time is later than the end time, a \"ValueError\" may occur.\n",
    "\n",
    "5.Missing or uninitialized values: If a function or operation requires a value to be provided, but it is missing or uninitialized, a \"ValueError\" can be raised. This often happens when variables or data structures are not properly initialized before use.\n",
    "\n",
    "6.Custom conditions: Developers can define their own conditions for raising a \"ValueError\" based on specific requirements of their program. These custom conditions can include any situation where a value is considered inappropriate or invalid.\n",
    "\n",
    "Remember, the specific reasons for a \"ValueError\" can vary depending on the programming language, the context in which it is raised, and the specific function or operation being performed. Reading the error message and understanding the expected behavior of the code will help in diagnosing the exact cause of the \"ValueError\"."
   ]
  },
  {
   "attachments": {},
   "cell_type": "markdown",
   "metadata": {},
   "source": [
    "8. Write code for the following given scenario and add try-exception block to it.\n",
    "\n",
    "a. Program to divide two numbers\n",
    "\n",
    "b. Program to convert a string to an integer\n",
    "\n",
    "c. Program to access an element in a list\n",
    "\n",
    "d. Program to handle a specific exception\n",
    "\n",
    "e. Program to handle any exception"
   ]
  },
  {
   "attachments": {},
   "cell_type": "markdown",
   "metadata": {},
   "source": [
    "Ans8. (a) a. Program to divide two numbers:"
   ]
  },
  {
   "cell_type": "code",
   "execution_count": null,
   "metadata": {},
   "outputs": [
    {
     "name": "stdout",
     "output_type": "stream",
     "text": [
      "Error: Division by zero is not allowed.\n"
     ]
    }
   ],
   "source": [
    "try:\n",
    "    dividend = float(input(\"Enter the dividend: \")) # 12 (input)\n",
    "    divisor = float(input(\"Enter the divisor: \")) # 0 (input)\n",
    "    result = dividend / divisor\n",
    "    print(\"Result: \", result)\n",
    "except ZeroDivisionError:\n",
    "    print(\"Error: Division by zero is not allowed.\")"
   ]
  },
  {
   "attachments": {},
   "cell_type": "markdown",
   "metadata": {},
   "source": [
    "(b) Program to convert a string to an integer:"
   ]
  },
  {
   "cell_type": "code",
   "execution_count": null,
   "metadata": {},
   "outputs": [
    {
     "name": "stdout",
     "output_type": "stream",
     "text": [
      "Error: Invalid input. Please enter a valid integer.\n"
     ]
    }
   ],
   "source": [
    "try:\n",
    "    num_str = input(\"Enter a number: \") #\n",
    "    num = int(num_str) # a\n",
    "    print(\"Number:\", num)\n",
    "except ValueError:\n",
    "    print(\"Error: Invalid input. Please enter a valid integer.\") "
   ]
  },
  {
   "attachments": {},
   "cell_type": "markdown",
   "metadata": {},
   "source": [
    "(c). Program to access an element in a list:"
   ]
  },
  {
   "cell_type": "code",
   "execution_count": null,
   "metadata": {},
   "outputs": [
    {
     "ename": "ValueError",
     "evalue": "invalid literal for int() with base 10: ''",
     "output_type": "error",
     "traceback": [
      "\u001b[1;31m---------------------------------------------------------------------------\u001b[0m",
      "\u001b[1;31mValueError\u001b[0m                                Traceback (most recent call last)",
      "Cell \u001b[1;32mIn[26], line 3\u001b[0m\n\u001b[0;32m      1\u001b[0m \u001b[39mtry\u001b[39;00m:\n\u001b[0;32m      2\u001b[0m     my_list \u001b[39m=\u001b[39m [\u001b[39m1\u001b[39m, \u001b[39m2\u001b[39m, \u001b[39m3\u001b[39m, \u001b[39m4\u001b[39m, \u001b[39m5\u001b[39m]\n\u001b[1;32m----> 3\u001b[0m     index \u001b[39m=\u001b[39m \u001b[39mint\u001b[39;49m(\u001b[39minput\u001b[39;49m(\u001b[39m\"\u001b[39;49m\u001b[39mEnter the index: \u001b[39;49m\u001b[39m\"\u001b[39;49m)) \u001b[39m# 7\u001b[39;00m\n\u001b[0;32m      4\u001b[0m     element \u001b[39m=\u001b[39m my_list[index]\n\u001b[0;32m      5\u001b[0m     \u001b[39mprint\u001b[39m(\u001b[39m\"\u001b[39m\u001b[39mElement:\u001b[39m\u001b[39m\"\u001b[39m, element)\n",
      "\u001b[1;31mValueError\u001b[0m: invalid literal for int() with base 10: ''"
     ]
    }
   ],
   "source": [
    "try:\n",
    "    my_list = [1, 2, 3, 4, 5]\n",
    "    index = int(input(\"Enter the index: \")) # 7\n",
    "    element = my_list[index]\n",
    "    print(\"Element:\", element)\n",
    "except IndexError:\n",
    "    print(\"Error: Index out of range.\")"
   ]
  },
  {
   "attachments": {},
   "cell_type": "markdown",
   "metadata": {},
   "source": [
    "(d). Program to handle a specific exception:"
   ]
  },
  {
   "cell_type": "code",
   "execution_count": null,
   "metadata": {},
   "outputs": [],
   "source": [
    "try:\n",
    "    # Code that may raise a specific exception\n",
    "    # ...\n",
    "except SpecificException:\n",
    "    # Exception handling code for SpecificException\n",
    "    # ..."
   ]
  },
  {
   "attachments": {},
   "cell_type": "markdown",
   "metadata": {},
   "source": [
    "Replace SpecificException with the actual specific exception you want to handle, such as ValueError, TypeError, etc."
   ]
  },
  {
   "attachments": {},
   "cell_type": "markdown",
   "metadata": {},
   "source": [
    "(e). Program to handle any exception:"
   ]
  },
  {
   "cell_type": "code",
   "execution_count": null,
   "metadata": {},
   "outputs": [],
   "source": [
    "try:\n",
    "    # Code that may raise an exception\n",
    "    # ...\n",
    "except Exception as e:\n",
    "    print(\"An error occurred:\", str(e))"
   ]
  },
  {
   "attachments": {},
   "cell_type": "markdown",
   "metadata": {},
   "source": [
    "This will catch any exception that occurs and print a generic error message along with the exception information. It's generally a good practice to handle exceptions more specifically whenever possible."
   ]
  }
 ],
 "metadata": {
  "kernelspec": {
   "display_name": "Python 3",
   "language": "python",
   "name": "python3"
  },
  "language_info": {
   "codemirror_mode": {
    "name": "ipython",
    "version": 3
   },
   "file_extension": ".py",
   "mimetype": "text/x-python",
   "name": "python",
   "nbconvert_exporter": "python",
   "pygments_lexer": "ipython3",
   "version": "3.11.4"
  },
  "orig_nbformat": 4
 },
 "nbformat": 4,
 "nbformat_minor": 2
}
